Workbook
Name MethodPointer1: 1763923488
Name MethodPointer2: 519

Sheet Plate 1 - Sheet1
A2: Software Version | B2: 3.10.06
A4: Experiment File Path: | B4: C:\Users\Public\Documents\Experiments\Erika\2024_12_02_MIC_MCF_C3.xpt
A5: Protocol File Path: | B5: C:\Users\Public\Documents\Protocols\InitialOD.prt
A6: Plate Number | B6: Plate 1
A7: Date | B7: 45994
A8: Time | B8: 0.6027662
A9: Reader Type: | B9: Epoch 2
A10: Reader Serial Number: | B10: 1803065
A11: Reading Type | B11: Reader
A13: Procedure Details
A14: Plate Type | B14: 96 WELL PLATE (Use plate lid)
A15: Eject plate on completion
A16: Read | B16: Absorbance Endpoint
B17: Full Plate
B18: Wavelengths: 600
B19: Read Speed: Normal, Delay: 100 msec, Measurements/Data Point: 8
A21: Layout
C23: 1 | D23: 2 | E23: 3 | F23: 4 | G23: 5 | H23: 6 | I23: 7 | J23: 8 | K23: 9 | L23: 10 | M23: 11 | N23: 12
B24: A | C24: SPL1 | D24: SPL9 | E24: SPL17 | F24: SPL25 | G24: SPL33 | H24: SPL41 | I24: SPL49 | J24: SPL57 | K24: SPL65 | L24: SPL73 | M24: SPL81 | N24: SPL89 | O24: Well ID
B25: B | C25: SPL2 | D25: SPL10 | E25: SPL18 | F25: SPL26 | G25: SPL34 | H25: SPL42 | I25: SPL50 | J25: SPL58 | K25: SPL66 | L25: SPL74 | M25: SPL82 | N25: SPL90 | O25: Well ID
B26: C | C26: SPL3 | D26: SPL11 | E26: SPL19 | F26: SPL27 | G26: SPL35 | H26: SPL43 | I26: SPL51 | J26: SPL59 | K26: SPL67 | L26: SPL75 | M26: SPL83 | N26: SPL91 | O26: Well ID
B27: D | C27: SPL4 | D27: SPL12 | E27: SPL20 | F27: SPL28 | G27: SPL36 | H27: SPL44 | I27: SPL52 | J27: SPL60 | K27: SPL68 | L27: SPL76 | M27: SPL84 | N27: SPL92 | O27: Well ID
B28: E | C28: SPL5 | D28: SPL13 | E28: SPL21 | F28: SPL29 | G28: SPL37 | H28: SPL45 | I28: SPL53 | J28: SPL61 | K28: SPL69 | L28: SPL77 | M28: SPL85 | N28: SPL93 | O28: Well ID
B29: F | C29: SPL6 | D29: SPL14 | E29: SPL22 | F29: SPL30 | G29: SPL38 | H29: SPL46 | I29: SPL54 | J29: SPL62 | K29: SPL70 | L29: SPL78 | M29: SPL86 | N29: SPL94 | O29: Well ID
B30: G | C30: SPL7 | D30: SPL15 | E30: SPL23 | F30: SPL31 | G30: SPL39 | H30: SPL47 | I30: SPL55 | J30: SPL63 | K30: SPL71 | L30: SPL79 | M30: SPL87 | N30: SPL95 | O30: Well ID
B31: H | C31: SPL8 | D31: SPL16 | E31: SPL24 | F31: SPL32 | G31: SPL40 | H31: SPL48 | I31: SPL56 | J31: SPL64 | K31: SPL72 | L31: SPL80 | M31: SPL88 | N31: SPL96 | O31: Well ID
A33: Results
A34: Actual Temperature: | B34: 24.1
C36: 1 | D36: 2 | E36: 3 | F36: 4 | G36: 5 | H36: 6 | I36: 7 | J36: 8 | K36: 9 | L36: 10 | M36: 11 | N36: 12
B37: A | C37: 0.105 | D37: 0.106 | E37: 0.113 | F37: 0.102 | G37: 0.098 | H37: 0.097 | I37: 0.099 | J37: 0.099 | K37: 0.098 | L37: 0.103 | M37: 0.106 | N37: 0.1 | O37: 600 | P37: =AVERAGE(C37:N37) -> 0.10216667
B38: B | C38: 1.16 | D38: 1.182 | E38: 1.182 | F38: 1.178 | G38: 1.161 | H38: 1.158 | I38: 1.203 | J38: 1.201 | K38: 1.204 | L38: 1.164 | M38: 1.186 | N38: 1.174 | O38: 600
B39: C | C39: 1.139 | D39: 1.171 | E39: 1.151 | F39: 1.15 | G39: 1.153 | H39: 1.146 | I39: 1.154 | J39: 1.151 | K39: 1.143 | L39: 1.108 | M39: 1.137 | N39: 1.118 | O39: 600
B40: D | C40: 1.117 | D40: 1.138 | E40: 1.115 | F40: 1.1 | G40: 1.129 | H40: 1.12 | I40: 1.098 | J40: 1.104 | K40: 1.089 | L40: 1.098 | M40: 1.093 | N40: 1.068 | O40: 600
B41: E | C41: 0.216 | D41: 0.276 | E41: 0.247 | F41: 0.147 | G41: 0.155 | H41: 0.151 | I41: 0.143 | J41: 0.138 | K41: 0.14 | L41: 0.142 | M41: 0.125 | N41: 0.124 | O41: 600
B42: F | C42: 0.107 | D42: 0.107 | E42: 0.107 | F42: 0.115 | G42: 0.118 | H42: 0.116 | I42: 0.114 | J42: 0.114 | K42: 0.119 | L42: 0.108 | M42: 0.101 | N42: 0.103 | O42: 600
B43: G | C43: 0.113 | D43: 0.11 | E43: 0.111 | F43: 0.108 | G43: 0.113 | H43: 0.113 | I43: 0.112 | J43: 0.111 | K43: 0.11 | L43: 0.102 | M43: 0.099 | N43: 0.1 | O43: 600
B44: H | C44: 0.12 | D44: 0.119 | E44: 0.12 | F44: 0.102 | G44: 0.101 | H44: 0.102 | I44: 0.102 | J44: 0.1 | K44: 0.099 | L44: 0.103 | M44: 0.101 | N44: 0.102 | O44: 600
C46: =C38-$P$37 -> 1.0578333 | D46: =D38-$P$37 -> 1.0798333 | E46: =E38-$P$37 -> 1.0798333 | F46: =F38-$P$37 -> 1.0758333 | G46: =G38-$P$37 -> 1.0588333 | H46: =H38-$P$37 -> 1.0558333 | I46: =I38-$P$37 -> 1.1008333 | J46: =J38-$P$37 -> 1.0988333 | ... N46: =N38-$P$37 -> 1.0718333
C47: =C39-$P$37 -> 1.0368333 | D47: =D39-$P$37 -> 1.0688333 | E47: =E39-$P$37 -> 1.0488333 | F47: =F39-$P$37 -> 1.0478333 | G47: =G39-$P$37 -> 1.0508333 | H47: =H39-$P$37 -> 1.0438333 | I47: =I39-$P$37 -> 1.0518333 | J47: =J39-$P$37 -> 1.0488333 | ... N47: =N39-$P$37 -> 1.0158333
C48: =C40-$P$37 -> 1.0148333 | D48: =D40-$P$37 -> 1.0358333 | E48: =E40-$P$37 -> 1.0128333 | F48: =F40-$P$37 -> 0.99783333 | G48: =G40-$P$37 -> 1.0268333 | H48: =H40-$P$37 -> 1.0178333 | I48: =I40-$P$37 -> 0.99583333 | J48: =J40-$P$37 -> 1.0018333 | ... N48: =N40-$P$37 -> 0.96583333
...

Sheet Plate 2 - Sheet1
A2: Software Version | B2: 3.10.06
A4: Experiment File Path: | B4: C:\Users\Public\Documents\Experiments\Erika\2024_12_02_MIC_MCF_C3.xpt
A5: Protocol File Path: | B5: C:\Users\Public\Documents\Protocols\InitialOD.prt
A6: Plate Number | B6: Plate 2
A7: Date | B7: 45994
A8: Time | B8: 0.60407407
A9: Reader Type: | B9: Epoch 2
A10: Reader Serial Number: | B10: 1803065
A11: Reading Type | B11: Reader
A13: Procedure Details
A14: Plate Type | B14: 96 WELL PLATE (Use plate lid)
A15: Eject plate on completion
A16: Read | B16: Absorbance Endpoint
B17: Full Plate
B18: Wavelengths: 600
B19: Read Speed: Normal, Delay: 100 msec, Measurements/Data Point: 8
A21: Layout
C23: 1 | D23: 2 | E23: 3 | F23: 4 | G23: 5 | H23: 6 | I23: 7 | J23: 8 | K23: 9 | L23: 10 | M23: 11 | N23: 12
B24: A | C24: SPL1 | D24: SPL9 | E24: SPL17 | F24: SPL25 | G24: SPL33 | H24: SPL41 | I24: SPL49 | J24: SPL57 | K24: SPL65 | L24: SPL73 | M24: SPL81 | N24: SPL89 | O24: Well ID
B25: B | C25: SPL2 | D25: SPL10 | E25: SPL18 | F25: SPL26 | G25: SPL34 | H25: SPL42 | I25: SPL50 | J25: SPL58 | K25: SPL66 | L25: SPL74 | M25: SPL82 | N25: SPL90 | O25: Well ID
B26: C | C26: SPL3 | D26: SPL11 | E26: SPL19 | F26: SPL27 | G26: SPL35 | H26: SPL43 | I26: SPL51 | J26: SPL59 | K26: SPL67 | L26: SPL75 | M26: SPL83 | N26: SPL91 | O26: Well ID
B27: D | C27: SPL4 | D27: SPL12 | E27: SPL20 | F27: SPL28 | G27: SPL36 | H27: SPL44 | I27: SPL52 | J27: SPL60 | K27: SPL68 | L27: SPL76 | M27: SPL84 | N27: SPL92 | O27: Well ID
B28: E | C28: SPL5 | D28: SPL13 | E28: SPL21 | F28: SPL29 | G28: SPL37 | H28: SPL45 | I28: SPL53 | J28: SPL61 | K28: SPL69 | L28: SPL77 | M28: SPL85 | N28: SPL93 | O28: Well ID
B29: F | C29: SPL6 | D29: SPL14 | E29: SPL22 | F29: SPL30 | G29: SPL38 | H29: SPL46 | I29: SPL54 | J29: SPL62 | K29: SPL70 | L29: SPL78 | M29: SPL86 | N29: SPL94 | O29: Well ID
B30: G | C30: SPL7 | D30: SPL15 | E30: SPL23 | F30: SPL31 | G30: SPL39 | H30: SPL47 | I30: SPL55 | J30: SPL63 | K30: SPL71 | L30: SPL79 | M30: SPL87 | N30: SPL95 | O30: Well ID
B31: H | C31: SPL8 | D31: SPL16 | E31: SPL24 | F31: SPL32 | G31: SPL40 | H31: SPL48 | I31: SPL56 | J31: SPL64 | K31: SPL72 | L31: SPL80 | M31: SPL88 | N31: SPL96 | O31: Well ID
A33: Results
A34: Actual Temperature: | B34: 24.1
C36: 1 | D36: 2 | E36: 3 | F36: 4 | G36: 5 | H36: 6 | I36: 7 | J36: 8 | K36: 9 | L36: 10 | M36: 11 | N36: 12
B37: A | C37: 0.097 | D37: 0.097 | E37: 0.099 | F37: 0.097 | G37: 0.098 | H37: 0.096 | I37: 0.098 | J37: 0.1 | K37: 0.097 | L37: 0.098 | M37: 0.098 | N37: 0.097 | O37: 600 | P37: =AVERAGE(C37:N37) -> 0.097666667
B38: B | C38: 1.617 | D38: 1.587 | E38: 1.534 | F38: 1.22 | G38: 1.213 | H38: 1.202 | I38: 1.221 | J38: 1.227 | K38: 1.218 | L38: 1.188 | M38: 1.183 | N38: 1.179 | O38: 600
B39: C | C39: 1.154 | D39: 1.168 | E39: 1.168 | F39: 1.169 | G39: 1.169 | H39: 1.166 | I39: 1.168 | J39: 1.18 | K39: 1.17 | L39: 1.134 | M39: 1.13 | N39: 1.121 | O39: 600
B40: D | C40: 1.131 | D40: 1.154 | E40: 1.138 | F40: 1.132 | G40: 1.136 | H40: 1.137 | I40: 1.109 | J40: 1.08 | K40: 1.103 | L40: 1.113 | M40: 1.089 | N40: 1.074 | O40: 600
B41: E | C41: 0.189 | D41: 0.232 | E41: 0.238 | F41: 0.149 | G41: 0.146 | H41: 0.147 | I41: 0.144 | J41: 0.141 | K41: 0.141 | L41: 0.146 | M41: 0.136 | N41: 0.13 | O41: 600
B42: F | C42: 0.117 | D42: 0.125 | E42: 0.126 | F42: 0.12 | G42: 0.122 | H42: 0.117 | I42: 0.118 | J42: 0.117 | K42: 0.115 | L42: 0.115 | M42: 0.111 | N42: 0.102 | O42: 600
B43: G | C43: 0.117 | D43: 0.125 | E43: 0.125 | F43: 0.111 | G43: 0.114 | H43: 0.114 | I43: 0.114 | J43: 0.115 | K43: 0.115 | L43: 0.118 | M43: 0.114 | N43: 0.1 | O43: 600
B44: H | C44: 0.124 | D44: 0.119 | E44: 0.128 | F44: 0.103 | G44: 0.103 | H44: 0.102 | I44: 0.101 | J44: 0.102 | K44: 0.1 | L44: 0.102 | M44: 0.101 | N44: 0.101 | O44: 600
C46: =C38-$P$37 -> 1.5193333 | D46: =D38-$P$37 -> 1.4893333 | E46: =E38-$P$37 -> 1.4363333 | F46: =F38-$P$37 -> 1.1223333 | G46: =G38-$P$37 -> 1.1153333 | H46: =H38-$P$37 -> 1.1043333 | I46: =I38-$P$37 -> 1.1233333 | J46: =J38-$P$37 -> 1.1293333 | ... N46: =N38-$P$37 -> 1.0813333
C47: =C39-$P$37 -> 1.0563333 | D47: =D39-$P$37 -> 1.0703333 | E47: =E39-$P$37 -> 1.0703333 | F47: =F39-$P$37 -> 1.0713333 | G47: =G39-$P$37 -> 1.0713333 | H47: =H39-$P$37 -> 1.0683333 | I47: =I39-$P$37 -> 1.0703333 | J47: =J39-$P$37 -> 1.0823333 | ... N47: =N39-$P$37 -> 1.0233333
C48: =C40-$P$37 -> 1.0333333 | D48: =D40-$P$37 -> 1.0563333 | E48: =E40-$P$37 -> 1.0403333 | F48: =F40-$P$37 -> 1.0343333 | G48: =G40-$P$37 -> 1.0383333 | H48: =H40-$P$37 -> 1.0393333 | I48: =I40-$P$37 -> 1.0113333 | J48: =J40-$P$37 -> 0.98233333 | ... N48: =N40-$P$37 -> 0.97633333
...

Sheet Plate 3 - Sheet1
A2: Software Version | B2: 3.10.06
A4: Experiment File Path: | B4: C:\Users\Public\Documents\Experiments\Erika\2024_12_02_MIC_MCF_C3.xpt
A5: Protocol File Path: | B5: C:\Users\Public\Documents\Protocols\InitialOD.prt
A6: Plate Number | B6: Plate 3
A7: Date | B7: 45994
A8: Time | B8: 0.60510417
A9: Reader Type: | B9: Epoch 2
A10: Reader Serial Number: | B10: 1803065
A11: Reading Type | B11: Reader
A13: Procedure Details
A14: Plate Type | B14: 96 WELL PLATE (Use plate lid)
A15: Eject plate on completion
A16: Read | B16: Absorbance Endpoint
B17: Full Plate
B18: Wavelengths: 600
B19: Read Speed: Normal, Delay: 100 msec, Measurements/Data Point: 8
A21: Layout
C23: 1 | D23: 2 | E23: 3 | F23: 4 | G23: 5 | H23: 6 | I23: 7 | J23: 8 | K23: 9 | L23: 10 | M23: 11 | N23: 12
B24: A | C24: SPL1 | D24: SPL9 | E24: SPL17 | F24: SPL25 | G24: SPL33 | H24: SPL41 | I24: SPL49 | J24: SPL57 | K24: SPL65 | L24: SPL73 | M24: SPL81 | N24: SPL89 | O24: Well ID
B25: B | C25: SPL2 | D25: SPL10 | E25: SPL18 | F25: SPL26 | G25: SPL34 | H25: SPL42 | I25: SPL50 | J25: SPL58 | K25: SPL66 | L25: SPL74 | M25: SPL82 | N25: SPL90 | O25: Well ID
B26: C | C26: SPL3 | D26: SPL11 | E26: SPL19 | F26: SPL27 | G26: SPL35 | H26: SPL43 | I26: SPL51 | J26: SPL59 | K26: SPL67 | L26: SPL75 | M26: SPL83 | N26: SPL91 | O26: Well ID
B27: D | C27: SPL4 | D27: SPL12 | E27: SPL20 | F27: SPL28 | G27: SPL36 | H27: SPL44 | I27: SPL52 | J27: SPL60 | K27: SPL68 | L27: SPL76 | M27: SPL84 | N27: SPL92 | O27: Well ID
B28: E | C28: SPL5 | D28: SPL13 | E28: SPL21 | F28: SPL29 | G28: SPL37 | H28: SPL45 | I28: SPL53 | J28: SPL61 | K28: SPL69 | L28: SPL77 | M28: SPL85 | N28: SPL93 | O28: Well ID
B29: F | C29: SPL6 | D29: SPL14 | E29: SPL22 | F29: SPL30 | G29: SPL38 | H29: SPL46 | I29: SPL54 | J29: SPL62 | K29: SPL70 | L29: SPL78 | M29: SPL86 | N29: SPL94 | O29: Well ID
B30: G | C30: SPL7 | D30: SPL15 | E30: SPL23 | F30: SPL31 | G30: SPL39 | H30: SPL47 | I30: SPL55 | J30: SPL63 | K30: SPL71 | L30: SPL79 | M30: SPL87 | N30: SPL95 | O30: Well ID
B31: H | C31: SPL8 | D31: SPL16 | E31: SPL24 | F31: SPL32 | G31: SPL40 | H31: SPL48 | I31: SPL56 | J31: SPL64 | K31: SPL72 | L31: SPL80 | M31: SPL88 | N31: SPL96 | O31: Well ID
A33: Results
A34: Actual Temperature: | B34: 24
C36: 1 | D36: 2 | E36: 3 | F36: 4 | G36: 5 | H36: 6 | I36: 7 | J36: 8 | K36: 9 | L36: 10 | M36: 11 | N36: 12
B37: A | C37: 0.098 | D37: 0.097 | E37: 0.098 | F37: 0.097 | G37: 0.096 | H37: 0.098 | I37: 0.097 | J37: 0.108 | K37: 0.097 | L37: 0.098 | M37: 0.098 | N37: 0.099 | O37: 600 | P37: =AVERAGE(C37:N37) -> 0.098416667
B38: B | C38: 1.158 | D38: 1.188 | E38: 1.175 | F38: 1.161 | G38: 1.169 | H38: 1.172 | I38: 1.21 | J38: 1.212 | K38: 1.206 | L38: 1.176 | M38: 1.181 | N38: 1.167 | O38: 600
B39: C | C39: 1.15 | D39: 1.156 | E39: 1.156 | F39: 1.139 | G39: 1.145 | H39: 1.148 | I39: 1.152 | J39: 1.16 | K39: 1.152 | L39: 1.129 | M39: 1.14 | N39: 1.121 | O39: 600
B40: D | C40: 1.115 | D40: 1.118 | E40: 1.121 | F40: 1.113 | G40: 1.121 | H40: 1.119 | I40: 1.098 | J40: 1.105 | K40: 1.097 | L40: 1.107 | M40: 1.097 | N40: 1.097 | O40: 600
B41: E | C41: 0.165 | D41: 0.203 | E41: 0.229 | F41: 0.136 | G41: 0.134 | H41: 0.132 | I41: 0.126 | J41: 0.123 | K41: 0.122 | L41: 0.13 | M41: 0.128 | N41: 0.128 | O41: 600
B42: F | C42: 0.113 | D42: 0.107 | E42: 0.105 | F42: 0.098 | G42: 0.104 | H42: 0.097 | I42: 0.103 | J42: 0.099 | K42: 0.102 | L42: 0.103 | M42: 0.102 | N42: 0.102 | O42: 600
B43: G | C43: 0.121 | D43: 0.119 | E43: 0.112 | F43: 0.106 | G43: 0.109 | H43: 0.104 | I43: 0.101 | J43: 0.1 | K43: 0.099 | L43: 0.101 | M43: 0.091 | N43: 0.099 | O43: 600
B44: H | C44: 0.135 | D44: 0.127 | E44: 0.124 | F44: 0.108 | G44: 0.103 | H44: 0.108 | I44: 0.099 | J44: 0.1 | K44: 0.1 | L44: 0.102 | M44: 0.1 | N44: 0.103 | O44: 600
C46: =C38-$P$37 -> 1.0595833 | D46: =D38-$P$37 -> 1.0895833 | E46: =E38-$P$37 -> 1.0765833 | F46: =F38-$P$37 -> 1.0625833 | G46: =G38-$P$37 -> 1.0705833 | H46: =H38-$P$37 -> 1.0735833 | I46: =I38-$P$37 -> 1.1115833 | J46: =J38-$P$37 -> 1.1135833 | ... N46: =N38-$P$37 -> 1.0685833
C47: =C39-$P$37 -> 1.0515833 | D47: =D39-$P$37 -> 1.0575833 | E47: =E39-$P$37 -> 1.0575833 | F47: =F39-$P$37 -> 1.0405833 | G47: =G39-$P$37 -> 1.0465833 | H47: =H39-$P$37 -> 1.0495833 | I47: =I39-$P$37 -> 1.0535833 | J47: =J39-$P$37 -> 1.0615833 | ... N47: =N39-$P$37 -> 1.0225833
C48: =C40-$P$37 -> 1.0165833 | D48: =D40-$P$37 -> 1.0195833 | E48: =E40-$P$37 -> 1.0225833 | F48: =F40-$P$37 -> 1.0145833 | G48: =G40-$P$37 -> 1.0225833 | H48: =H40-$P$37 -> 1.0205833 | I48: =I40-$P$37 -> 0.99958333 | J48: =J40-$P$37 -> 1.0065833 | ... N48: =N40-$P$37 -> 0.99858333
...
