Workbook
Name MethodPointer1: 879390416
Name MethodPointer2: 474

Sheet guide1Rep1
A2: Software Version | B2: 3.16.10
A4: Experiment File Path: | B4: C:\Users\Plate Reader Access\Desktop\Selmecki lab\Petra\mic_2025_06_04.xpt
A5: Protocol File Path: | B5: C:\Users\Public\Documents\Protocols\InitialOD.prt
A6: Plate Number | B6: Plate 4
A7: Date | B7: 45812
A8: Time | B8: 0.61015046
A9: Reader Type: | B9: Synergy H1
A10: Reader Serial Number: | B10: 25030902
A11: Reading Type | B11: Reader
A13: Procedure Details
A14: Plate Type | B14: 96 WELL PLATE (Use plate lid)
A15: Eject plate on completion
A16: Read | B16: Absorbance Endpoint
B17: Full Plate
B18: Wavelengths: 600
B19: Read Speed: Normal, Delay: 100 msec, Measurements/Data Point: 8
A21: Results
A22: Actual Temperature: | B22: 30
C23: AMS2401 | D23: P75063 | E23: P75016 | F23: L26 | G23: AMS5192 | H23: AMS2401 guide 1 | I23: P75063 guide 1 | J23: P75016 guide 1 | K23: L26 guide 1 | L23: AMS5192 guide 1 | M23: AMS2401 guide 1 transformant 2 | N23: L26 guide 1 transformant 2
C24: 1 | D24: 2 | E24: 3 | F24: 4 | G24: 5 | H24: 6 | I24: 7 | J24: 8 | K24: 9 | L24: 10 | M24: 11 | N24: 12
B25: A | C25: 0.103 | D25: 0.097 | E25: 0.098 | F25: 0.097 | G25: 0.097 | H25: 0.099 | I25: 0.103 | J25: 0.101 | K25: 0.102 | L25: 0.106 | M25: 0.105 | N25: 0.099 | O25: 600 | P25: =AVERAGE(C25:N25) -> 0.10058333
B26: B | C26: 1.336 | D26: 1.497 | E26: 1.463 | F26: 1.473 | G26: 1.492 | H26: 1.448 | I26: 1.512 | J26: 1.451 | K26: 1.463 | L26: 1.454 | M26: 1.447 | N26: 1.38 | O26: 600
B27: C | C27: 1.274 | D27: 1.154 | E27: 1.463 | F27: 1.5 | G27: 1.294 | H27: 1.518 | I27: 1.519 | J27: 1.496 | K27: 1.503 | L27: 1.471 | M27: 1.482 | N27: 1.415 | O27: 600
B28: D | C28: 0.348 | D28: 0.519 | E28: 0.521 | F28: 1.491 | G28: 0.414 | H28: 1.506 | I28: 1.537 | J28: 1.505 | K28: 1.502 | L28: 1.465 | M28: 1.481 | N28: 1.421 | O28: 600
B29: E | C29: 0.197 | D29: 0.309 | E29: 0.336 | F29: 1.446 | G29: 0.314 | H29: 1.479 | I29: 0.648 | J29: 0.499 | K29: 1.463 | L29: 1.457 | M29: 1.472 | N29: 1.413 | O29: 600
B30: F | C30: 0.148 | D30: 0.287 | E30: 0.294 | F30: 0.589 | G30: 0.288 | H30: 0.408 | I30: 0.334 | J30: 0.299 | K30: 1.459 | L30: 0.43 | M30: 0.371 | N30: 1.394 | O30: 600
B31: G | C31: 0.131 | D31: 0.28 | E31: 0.259 | F31: 0.298 | G31: 0.264 | H31: 0.294 | I31: 0.293 | J31: 0.277 | K31: 0.4 | L31: 0.245 | M31: 0.25 | N31: 0.316 | O31: 600
B32: H | C32: 0.125 | D32: 0.168 | E32: 0.141 | F32: 0.152 | G32: 0.158 | H32: 0.181 | I32: 0.215 | J32: 0.217 | K32: 0.195 | L32: 0.191 | M32: 0.174 | N32: 0.152 | O32: 600
C35: =C26-$P$25 -> 1.2354167 | D35: =D26-$P$25 -> 1.3964167 | E35: =E26-$P$25 -> 1.3624167 | F35: =F26-$P$25 -> 1.3724167 | G35: =G26-$P$25 -> 1.3914167 | H35: =H26-$P$25 -> 1.3474167 | I35: =I26-$P$25 -> 1.4114167 | J35: =J26-$P$25 -> 1.3504167 | ... N35: =N26-$P$25 -> 1.2794167
C36: =C27-$P$25 -> 1.1734167 | D36: =D27-$P$25 -> 1.0534167 | E36: =E27-$P$25 -> 1.3624167 | F36: =F27-$P$25 -> 1.3994167 | G36: =G27-$P$25 -> 1.1934167 | H36: =H27-$P$25 -> 1.4174167 | I36: =I27-$P$25 -> 1.4184167 | J36: =J27-$P$25 -> 1.3954167 | ... N36: =N27-$P$25 -> 1.3144167
C37: =C28-$P$25 -> 0.24741667 | D37: =D28-$P$25 -> 0.41841667 | E37: =E28-$P$25 -> 0.42041667 | F37: =F28-$P$25 -> 1.3904167 | G37: =G28-$P$25 -> 0.31341667 | H37: =H28-$P$25 -> 1.4054167 | I37: =I28-$P$25 -> 1.4364167 | J37: =J28-$P$25 -> 1.4044167 | ... N37: =N28-$P$25 -> 1.3204167
C38: =C29-$P$25 -> 0.096416667 | D38: =D29-$P$25 -> 0.20841667 | E38: =E29-$P$25 -> 0.23541667 | F38: =F29-$P$25 -> 1.3454167 | G38: =G29-$P$25 -> 0.21341667 | H38: =H29-$P$25 -> 1.3784167 | I38: =I29-$P$25 -> 0.54741667 | J38: =J29-$P$25 -> 0.39841667 | ... N38: =N29-$P$25 -> 1.3124167
C39: =C30-$P$25 -> 0.047416667 | D39: =D30-$P$25 -> 0.18641667 | E39: =E30-$P$25 -> 0.19341667 | F39: =F30-$P$25 -> 0.48841667 | G39: =G30-$P$25 -> 0.18741667 | H39: =H30-$P$25 -> 0.30741667 | I39: =I30-$P$25 -> 0.23341667 | J39: =J30-$P$25 -> 0.19841667 | ... N39: =N30-$P$25 -> 1.2934167
C40: =C31-$P$25 -> 0.030416667 | D40: =D31-$P$25 -> 0.17941667 | E40: =E31-$P$25 -> 0.15841667 | F40: =F31-$P$25 -> 0.19741667 | G40: =G31-$P$25 -> 0.16341667 | H40: =H31-$P$25 -> 0.19341667 | I40: =I31-$P$25 -> 0.19241667 | J40: =J31-$P$25 -> 0.17641667 | ... N40: =N31-$P$25 -> 0.21541667
C41: =C32-$P$25 -> 0.024416667 | D41: =D32-$P$25 -> 0.067416667 | E41: =E32-$P$25 -> 0.040416667 | F41: =F32-$P$25 -> 0.051416667 | G41: =G32-$P$25 -> 0.057416667 | H41: =H32-$P$25 -> 0.080416667 | I41: =I32-$P$25 -> 0.11441667 | J41: =J32-$P$25 -> 0.11641667 | ... N41: =N32-$P$25 -> 0.051416667
C43: =C35/$C$35 -> 1 | D43: =D35/$D$35 -> 1 | E43: =E35/$E$35 -> 1 | F43: =F35/$F$35 -> 1 | G43: =G35/$G$35 -> 1 | H43: =H35/$H$35 -> 1 | I43: =I35/$I$35 -> 1 | J43: =J35/$J$35 -> 1 | K43: =K35/$K$35 -> 1 | L43: =L35/$L$35 -> 1 | M43: =M35/$M$35 -> 1 | N43: =N35/$N$35 -> 1
C44: =C36/$C$35 -> 0.9498145 | D44: =D36/$D$35 -> 0.75437131 | E44: =E36/$E$35 -> 1 | F44: =F36/$F$35 -> 1.0196733 | G44: =G36/$G$35 -> 0.85769899 | H44: =H36/$H$35 -> 1.0519513 | I44: =I36/$I$35 -> 1.0049596 | J44: =J36/$J$35 -> 1.033323 | K44: =K36/$K$35 -> 1.0293596 | L44: =L36/$L$35 -> 1.0125608 | M44: =M36/$M$35 -> 1.0259949 | N44: =N36/$N$35 -> 1.0273562
C45: =C37/$C$35 -> 0.20026981 | D45: =D37/$D$35 -> 0.29963597 | E45: =E37/$E$35 -> 0.30858156 | F45: =F37/$F$35 -> 1.0131156 | G45: =G37/$G$35 -> 0.22525004 | H45: =H37/$H$35 -> 1.0430453 | I45: =I37/$I$35 -> 1.0177127 | J45: =J37/$J$35 -> 1.0399877 | K45: =K37/$K$35 -> 1.0286256 | L45: =L37/$L$35 -> 1.0081276 | M45: =M37/$M$35 -> 1.0252522 | N45: =N37/$N$35 -> 1.0320459
C46: =C38/$C$35 -> 0.078043845 | D46: =D38/$D$35 -> 0.14925106 | E46: =E38/$E$35 -> 0.17279344 | F46: =F38/$F$35 -> 0.98032667 | G46: =G38/$G$35 -> 0.15338085 | H46: =H38/$H$35 -> 1.023007 | I46: =I38/$I$35 -> 0.38784909 | J46: =J38/$J$35 -> 0.2950324 | K46: =K38/$K$35 -> 1 | L46: =L38/$L$35 -> 1.0022166 | M46: =M38/$M$35 -> 1.0185678 | N46: =N38/$N$35 -> 1.025793
C47: =C39/$C$35 -> 0.038381113 | D47: =D39/$D$35 -> 0.13349645 | E47: =E39/$E$35 -> 0.14196587 | F47: =F39/$F$35 -> 0.35588075 | G47: =G39/$G$35 -> 0.13469486 | H47: =H39/$H$35 -> 0.22815264 | I47: =I39/$I$35 -> 0.16537758 | J47: =J39/$J$35 -> 0.14692996 | K47: =K39/$K$35 -> 0.99706404 | L47: =L39/$L$35 -> 0.24339634 | M47: =M39/$M$35 -> 0.20084174 | N47: =N39/$N$35 -> 1.0109425
...

Sheet guide1Rep2
A2: Software Version | B2: 3.16.10
A4: Experiment File Path: | B4: C:\Users\Plate Reader Access\Desktop\Selmecki lab\Petra\mic_2025_06_04.xpt
A5: Protocol File Path: | B5: C:\Users\Public\Documents\Protocols\InitialOD.prt
A6: Plate Number | B6: Plate 5
A7: Date | B7: 45812
A8: Time | B8: 0.61099537
A9: Reader Type: | B9: Synergy H1
A10: Reader Serial Number: | B10: 25030902
A11: Reading Type | B11: Reader
A13: Procedure Details
A14: Plate Type | B14: 96 WELL PLATE (Use plate lid)
A15: Eject plate on completion
A16: Read | B16: Absorbance Endpoint
B17: Full Plate
B18: Wavelengths: 600
B19: Read Speed: Normal, Delay: 100 msec, Measurements/Data Point: 8
A21: Results
A22: Actual Temperature: | B22: 29.9
C24: 1 | D24: 2 | E24: 3 | F24: 4 | G24: 5 | H24: 6 | I24: 7 | J24: 8 | K24: 9 | L24: 10 | M24: 11 | N24: 12
B25: A | C25: 0.097 | D25: 0.103 | E25: 0.108 | F25: 0.107 | G25: 0.108 | H25: 0.098 | I25: 0.112 | J25: 0.104 | K25: 0.107 | L25: 0.104 | M25: 0.097 | N25: 0.097 | O25: 600 | P25: =AVERAGE(C25:N25) -> 0.1035
B26: B | C26: 1.271 | D26: 1.335 | E26: 1.325 | F26: 1.309 | G26: 1.376 | H26: 1.325 | I26: 1.451 | J26: 1.407 | K26: 1.42 | L26: 1.447 | M26: 1.421 | N26: 1.395 | O26: 600
B27: C | C27: 1.287 | D27: 1.123 | E27: 1.424 | F27: 1.44 | G27: 1.236 | H27: 1.433 | I27: 1.501 | J27: 1.455 | K27: 1.464 | L27: 1.468 | M27: 1.431 | N27: 1.434 | O27: 600
B28: D | C28: 0.369 | D28: 0.477 | E28: 0.506 | F28: 1.442 | G28: 0.381 | H28: 1.444 | I28: 1.513 | J28: 1.466 | K28: 1.454 | L28: 1.419 | M28: 1.368 | N28: 1.379 | O28: 600
B29: E | C29: 0.179 | D29: 0.257 | E29: 0.253 | F29: 1.365 | G29: 0.23 | H29: 1.431 | I29: 0.616 | J29: 0.445 | K29: 1.424 | L29: 1.422 | M29: 1.373 | N29: 1.388 | O29: 600
B30: F | C30: 0.15 | D30: 0.227 | E30: 0.205 | F30: 0.494 | G30: 0.196 | H30: 0.342 | I30: 0.264 | J30: 0.239 | K30: 1.417 | L30: 0.378 | M30: 0.341 | N30: 1.347 | O30: 600
B31: G | C31: 0.133 | D31: 0.186 | E31: 0.184 | F31: 0.2 | G31: 0.184 | H31: 0.197 | I31: 0.226 | J31: 0.219 | K31: 0.333 | L31: 0.197 | M31: 0.181 | N31: 0.328 | O31: 600
B32: H | C32: 0.122 | D32: 0.174 | E32: 0.157 | F32: 0.136 | G32: 0.151 | H32: 0.158 | I32: 0.187 | J32: 0.172 | K32: 0.156 | L32: 0.147 | M32: 0.16 | N32: 0.158 | O32: 600
C35: =C26-$P$25 -> 1.1675 | D35: =D26-$P$25 -> 1.2315 | E35: =E26-$P$25 -> 1.2215 | F35: =F26-$P$25 -> 1.2055 | G35: =G26-$P$25 -> 1.2725 | H35: =H26-$P$25 -> 1.2215 | I35: =I26-$P$25 -> 1.3475 | J35: =J26-$P$25 -> 1.3035 | ... N35: =N26-$P$25 -> 1.2915
C36: =C27-$P$25 -> 1.1835 | D36: =D27-$P$25 -> 1.0195 | E36: =E27-$P$25 -> 1.3205 | F36: =F27-$P$25 -> 1.3365 | G36: =G27-$P$25 -> 1.1325 | H36: =H27-$P$25 -> 1.3295 | I36: =I27-$P$25 -> 1.3975 | J36: =J27-$P$25 -> 1.3515 | ... N36: =N27-$P$25 -> 1.3305
C37: =C28-$P$25 -> 0.2655 | D37: =D28-$P$25 -> 0.3735 | E37: =E28-$P$25 -> 0.4025 | F37: =F28-$P$25 -> 1.3385 | G37: =G28-$P$25 -> 0.2775 | H37: =H28-$P$25 -> 1.3405 | I37: =I28-$P$25 -> 1.4095 | J37: =J28-$P$25 -> 1.3625 | ... N37: =N28-$P$25 -> 1.2755
C38: =C29-$P$25 -> 0.0755 | D38: =D29-$P$25 -> 0.1535 | E38: =E29-$P$25 -> 0.1495 | F38: =F29-$P$25 -> 1.2615 | G38: =G29-$P$25 -> 0.1265 | H38: =H29-$P$25 -> 1.3275 | I38: =I29-$P$25 -> 0.5125 | J38: =J29-$P$25 -> 0.3415 | ... N38: =N29-$P$25 -> 1.2845
C39: =C30-$P$25 -> 0.0465 | D39: =D30-$P$25 -> 0.1235 | E39: =E30-$P$25 -> 0.1015 | F39: =F30-$P$25 -> 0.3905 | G39: =G30-$P$25 -> 0.0925 | H39: =H30-$P$25 -> 0.2385 | I39: =I30-$P$25 -> 0.1605 | J39: =J30-$P$25 -> 0.1355 | ... N39: =N30-$P$25 -> 1.2435
C40: =C31-$P$25 -> 0.0295 | D40: =D31-$P$25 -> 0.0825 | E40: =E31-$P$25 -> 0.0805 | F40: =F31-$P$25 -> 0.0965 | G40: =G31-$P$25 -> 0.0805 | H40: =H31-$P$25 -> 0.0935 | I40: =I31-$P$25 -> 0.1225 | J40: =J31-$P$25 -> 0.1155 | ... N40: =N31-$P$25 -> 0.2245
C41: =C32-$P$25 -> 0.0185 | D41: =D32-$P$25 -> 0.0705 | E41: =E32-$P$25 -> 0.0535 | F41: =F32-$P$25 -> 0.0325 | G41: =G32-$P$25 -> 0.0475 | H41: =H32-$P$25 -> 0.0545 | I41: =I32-$P$25 -> 0.0835 | J41: =J32-$P$25 -> 0.0685 | ... N41: =N32-$P$25 -> 0.0545
C43: =C35/$C$35 -> 1 | D43: =D35/$D$35 -> 1 | E43: =E35/$E$35 -> 1 | F43: =F35/$F$35 -> 1 | G43: =G35/$G$35 -> 1 | H43: =H35/$H$35 -> 1 | I43: =I35/$I$35 -> 1 | J43: =J35/$J$35 -> 1 | K43: =K35/$K$35 -> 1 | L43: =L35/$L$35 -> 1 | M43: =M35/$M$35 -> 1 | N43: =N35/$N$35 -> 1
C44: =C36/$C$35 -> 1.0137045 | D44: =D36/$D$35 -> 0.82785221 | E44: =E36/$E$35 -> 1.0810479 | F44: =F36/$F$35 -> 1.1086686 | G44: =G36/$G$35 -> 0.88998035 | H44: =H36/$H$35 -> 1.0884159 | I44: =I36/$I$35 -> 1.0371058 | J44: =J36/$J$35 -> 1.0368239 | K44: =K36/$K$35 -> 1.033422 | L44: =L36/$L$35 -> 1.0156308 | M44: =M36/$M$35 -> 1.0075901 | N44: =N36/$N$35 -> 1.0301974
C45: =C37/$C$35 -> 0.22740899 | D45: =D37/$D$35 -> 0.30328867 | E45: =E37/$E$35 -> 0.32951289 | F45: =F37/$F$35 -> 1.1103277 | G45: =G37/$G$35 -> 0.21807466 | H45: =H37/$H$35 -> 1.0974212 | I45: =I37/$I$35 -> 1.0460111 | J45: =J37/$J$35 -> 1.0452628 | K45: =K37/$K$35 -> 1.0258261 | L45: =L37/$L$35 -> 0.97915891 | M45: =M37/$M$35 -> 0.9597723 | N45: =N37/$N$35 -> 0.9876113
C46: =C38/$C$35 -> 0.064668094 | D46: =D38/$D$35 -> 0.12464474 | E46: =E38/$E$35 -> 0.1223905 | F46: =F38/$F$35 -> 1.0464538 | G46: =G38/$G$35 -> 0.099410609 | H46: =H38/$H$35 -> 1.0867786 | I46: =I38/$I$35 -> 0.38033395 | J46: =J38/$J$35 -> 0.26198696 | K46: =K38/$K$35 -> 1.0030384 | L46: =L38/$L$35 -> 0.98139189 | M46: =M38/$M$35 -> 0.96356736 | N46: =N38/$N$35 -> 0.99457995
C47: =C39/$C$35 -> 0.039828694 | D47: =D39/$D$35 -> 0.10028421 | E47: =E39/$E$35 -> 0.083094556 | F47: =F39/$F$35 -> 0.32393198 | G47: =G39/$G$35 -> 0.072691552 | H47: =H39/$H$35 -> 0.19525174 | I47: =I39/$I$35 -> 0.11910946 | J47: =J39/$J$35 -> 0.1039509 | K47: =K39/$K$35 -> 0.99772123 | L47: =L39/$L$35 -> 0.20431708 | M47: =M39/$M$35 -> 0.18026565 | N47: =N39/$N$35 -> 0.96283391
C48: =C40/$C$35 -> 0.025267666 | D48: =D40/$D$35 -> 0.066991474 | E48: =E40/$E$35 -> 0.065902579 | F48: =F40/$F$35 -> 0.080049772 | G48: =G40/$G$35 -> 0.063261297 | H48: =H40/$H$35 -> 0.076545231 | I48: =I40/$I$35 -> 0.090909091 | J48: =J40/$J$35 -> 0.088607595 | K48: =K40/$K$35 -> 0.17432586 | L48: =L40/$L$35 -> 0.069594343 | M48: =M40/$M$35 -> 0.058823529 | N48: =N40/$N$35 -> 0.17382888
...

Sheet guide1Rep3, analysis
A2: Software Version | B2: 3.16.10
A4: Experiment File Path: | B4: C:\Users\Plate Reader Access\Desktop\Selmecki lab\Petra\mic_2025_06_04.xpt
A5: Protocol File Path: | B5: C:\Users\Public\Documents\Protocols\InitialOD.prt
A6: Plate Number | B6: Plate 6
A7: Date | B7: 45812
A8: Time | B8: 0.6118287
A9: Reader Type: | B9: Synergy H1
A10: Reader Serial Number: | B10: 25030902
A11: Reading Type | B11: Reader
A13: Procedure Details
A14: Plate Type | B14: 96 WELL PLATE (Use plate lid)
A15: Eject plate on completion
A16: Read | B16: Absorbance Endpoint
B17: Full Plate
B18: Wavelengths: 600
B19: Read Speed: Normal, Delay: 100 msec, Measurements/Data Point: 8
A21: Results
A22: Actual Temperature: | B22: 29.8
C24: 1 | D24: 2 | E24: 3 | F24: 4 | G24: 5 | H24: 6 | I24: 7 | J24: 8 | K24: 9 | L24: 10 | M24: 11 | N24: 12
B25: A | C25: 0.1 | D25: 0.096 | E25: 0.096 | F25: 0.097 | G25: 0.096 | H25: 0.097 | I25: 0.099 | J25: 0.097 | K25: 0.099 | L25: 0.097 | M25: 0.097 | N25: 0.109 | O25: 600 | P25: =AVERAGE(C25:N25) -> 0.098333333
B26: B | C26: 1.324 | D26: 1.484 | E26: 1.455 | F26: 1.405 | G26: 1.435 | H26: 1.419 | I26: 1.483 | J26: 1.387 | K26: 1.401 | L26: 1.429 | M26: 1.426 | N26: 1.426 | O26: 600
B27: C | C27: 1.177 | D27: 1.147 | E27: 1.421 | F27: 1.402 | G27: 1.15 | H27: 1.404 | I27: 1.489 | J27: 1.333 | K27: 1.349 | L27: 1.387 | M27: 1.404 | N27: 1.396 | O27: 600
B28: D | C28: 0.391 | D28: 0.469 | E28: 0.502 | F28: 1.449 | G28: 0.369 | H28: 1.459 | I28: 1.499 | J28: 1.434 | K28: 1.437 | L28: 1.457 | M28: 1.422 | N28: 1.426 | O28: 600
B29: E | C29: 0.215 | D29: 0.24 | E29: 0.236 | F29: 1.37 | G29: 0.228 | H29: 1.436 | I29: 0.621 | J29: 0.488 | K29: 1.418 | L29: 1.442 | M29: 1.405 | N29: 1.408 | O29: 600
B30: F | C30: 0.139 | D30: 0.188 | E30: 0.178 | F30: 0.485 | G30: 0.184 | H30: 0.329 | I30: 0.234 | J30: 0.233 | K30: 1.406 | L30: 0.394 | M30: 0.337 | N30: 1.38 | O30: 600
B31: G | C31: 0.135 | D31: 0.176 | E31: 0.147 | F31: 0.183 | G31: 0.167 | H31: 0.193 | I31: 0.205 | J31: 0.181 | K31: 0.324 | L31: 0.171 | M31: 0.175 | N31: 0.352 | O31: 600
B32: H | C32: 0.128 | D32: 0.179 | E32: 0.144 | F32: 0.147 | G32: 0.141 | H32: 0.157 | I32: 0.185 | J32: 0.167 | K32: 0.159 | L32: 0.15 | M32: 0.149 | N32: 0.16 | O32: 600
C35: =C26-$P$25 -> 1.2256667 | D35: =D26-$P$25 -> 1.3856667 | E35: =E26-$P$25 -> 1.3566667 | F35: =F26-$P$25 -> 1.3066667 | G35: =G26-$P$25 -> 1.3366667 | H35: =H26-$P$25 -> 1.3206667 | I35: =I26-$P$25 -> 1.3846667 | J35: =J26-$P$25 -> 1.2886667 | ... N35: =N26-$P$25 -> 1.3276667
C36: =C27-$P$25 -> 1.0786667 | D36: =D27-$P$25 -> 1.0486667 | E36: =E27-$P$25 -> 1.3226667 | F36: =F27-$P$25 -> 1.3036667 | G36: =G27-$P$25 -> 1.0516667 | H36: =H27-$P$25 -> 1.3056667 | I36: =I27-$P$25 -> 1.3906667 | J36: =J27-$P$25 -> 1.2346667 | ... N36: =N27-$P$25 -> 1.2976667
C37: =C28-$P$25 -> 0.29266667 | D37: =D28-$P$25 -> 0.37066667 | E37: =E28-$P$25 -> 0.40366667 | F37: =F28-$P$25 -> 1.3506667 | G37: =G28-$P$25 -> 0.27066667 | H37: =H28-$P$25 -> 1.3606667 | I37: =I28-$P$25 -> 1.4006667 | J37: =J28-$P$25 -> 1.3356667 | ... N37: =N28-$P$25 -> 1.3276667
C38: =C29-$P$25 -> 0.11666667 | D38: =D29-$P$25 -> 0.14166667 | E38: =E29-$P$25 -> 0.13766667 | F38: =F29-$P$25 -> 1.2716667 | G38: =G29-$P$25 -> 0.12966667 | H38: =H29-$P$25 -> 1.3376667 | I38: =I29-$P$25 -> 0.52266667 | J38: =J29-$P$25 -> 0.38966667 | ... N38: =N29-$P$25 -> 1.3096667
C39: =C30-$P$25 -> 0.040666667 | D39: =D30-$P$25 -> 0.089666667 | E39: =E30-$P$25 -> 0.079666667 | F39: =F30-$P$25 -> 0.38666667 | G39: =G30-$P$25 -> 0.085666667 | H39: =H30-$P$25 -> 0.23066667 | I39: =I30-$P$25 -> 0.13566667 | J39: =J30-$P$25 -> 0.13466667 | ... N39: =N30-$P$25 -> 1.2816667
C40: =C31-$P$25 -> 0.036666667 | D40: =D31-$P$25 -> 0.077666667 | E40: =E31-$P$25 -> 0.048666667 | F40: =F31-$P$25 -> 0.084666667 | G40: =G31-$P$25 -> 0.068666667 | H40: =H31-$P$25 -> 0.094666667 | I40: =I31-$P$25 -> 0.10666667 | J40: =J31-$P$25 -> 0.082666667 | ... N40: =N31-$P$25 -> 0.25366667
C41: =C32-$P$25 -> 0.029666667 | D41: =D32-$P$25 -> 0.080666667 | E41: =E32-$P$25 -> 0.045666667 | F41: =F32-$P$25 -> 0.048666667 | G41: =G32-$P$25 -> 0.042666667 | H41: =H32-$P$25 -> 0.058666667 | I41: =I32-$P$25 -> 0.086666667 | J41: =J32-$P$25 -> 0.068666667 | ... N41: =N32-$P$25 -> 0.061666667
C43: =C35/$C$35 -> 1 | D43: =D35/$D$35 -> 1 | E43: =E35/$E$35 -> 1 | F43: =F35/$F$35 -> 1 | G43: =G35/$G$35 -> 1 | H43: =H35/$H$35 -> 1 | I43: =I35/$I$35 -> 1 | J43: =J35/$J$35 -> 1 | K43: =K35/$K$35 -> 1 | L43: =L35/$L$35 -> 1 | M43: =M35/$M$35 -> 1 | N43: =N35/$N$35 -> 1
C44: =C36/$C$35 -> 0.88006527 | D44: =D36/$D$35 -> 0.75679577 | E44: =E36/$E$35 -> 0.97493857 | F44: =F36/$F$35 -> 0.99770408 | G44: =G36/$G$35 -> 0.78678304 | H44: =H36/$H$35 -> 0.9886421 | I44: =I36/$I$35 -> 1.0043332 | J44: =J36/$J$35 -> 0.95809622 | K44: =K36/$K$35 -> 0.96008188 | L44: =L36/$L$35 -> 0.96843687 | M44: =M36/$M$35 -> 0.98342958 | N44: =N36/$N$35 -> 0.97740397
C45: =C37/$C$35 -> 0.23878162 | D45: =D37/$D$35 -> 0.2675006 | E45: =E37/$E$35 -> 0.297543 | F45: =F37/$F$35 -> 1.0336735 | G45: =G37/$G$35 -> 0.20249377 | H45: =H37/$H$35 -> 1.0302877 | I45: =I37/$I$35 -> 1.0115551 | J45: =J37/$J$35 -> 1.0364718 | K45: =K37/$K$35 -> 1.0276356 | L45: =L37/$L$35 -> 1.0210421 | M45: =M37/$M$35 -> 0.9969872 | N45: =N37/$N$35 -> 1
C46: =C38/$C$35 -> 0.095186293 | D46: =D38/$D$35 -> 0.10223719 | E46: =E38/$E$35 -> 0.1014742 | F46: =F38/$F$35 -> 0.97321429 | G46: =G38/$G$35 -> 0.097007481 | H46: =H38/$H$35 -> 1.0128723 | I46: =I38/$I$35 -> 0.3774675 | J46: =J38/$J$35 -> 0.30237972 | K46: =K38/$K$35 -> 1.0130502 | L46: =L38/$L$35 -> 1.0097695 | M46: =M38/$M$35 -> 0.98418278 | N46: =N38/$N$35 -> 0.98644238
C47: =C39/$C$35 -> 0.033179222 | D47: =D39/$D$35 -> 0.064710127 | E47: =E39/$E$35 -> 0.058722359 | F47: =F39/$F$35 -> 0.29591837 | G47: =G39/$G$35 -> 0.064089776 | H47: =H39/$H$35 -> 0.17465926 | I47: =I39/$I$35 -> 0.097977853 | J47: =J39/$J$35 -> 0.10450078 | K47: =K39/$K$35 -> 1.0038383 | L47: =L39/$L$35 -> 0.22219439 | M47: =M39/$M$35 -> 0.179764 | N47: =N39/$N$35 -> 0.96535275
C48: =C40/$C$35 -> 0.029915692 | D48: =D40/$D$35 -> 0.056050036 | E48: =E40/$E$35 -> 0.035872236 | F48: =F40/$F$35 -> 0.064795918 | G48: =G40/$G$35 -> 0.051371571 | H48: =H40/$H$35 -> 0.071680969 | I48: =I40/$I$35 -> 0.077034184 | J48: =J40/$J$35 -> 0.064148991 | K48: =K40/$K$35 -> 0.17323439 | L48: =L40/$L$35 -> 0.054609218 | M48: =M40/$M$35 -> 0.057745418 | N48: =N40/$N$35 -> 0.19106201
...

Sheet guide2Rep1
A2: Software Version | B2: 3.16.10
A4: Experiment File Path: | B4: C:\Users\Plate Reader Access\Desktop\Selmecki lab\Petra\mic_2025_06_04.xpt
A5: Protocol File Path: | B5: C:\Users\Public\Documents\Protocols\InitialOD.prt
A6: Plate Number | B6: Plate 7
A7: Date | B7: 45812
A8: Time | B8: 0.616875
A9: Reader Type: | B9: Synergy H1
A10: Reader Serial Number: | B10: 25030902
A11: Reading Type | B11: Reader
A13: Procedure Details
A14: Plate Type | B14: 96 WELL PLATE (Use plate lid)
A15: Eject plate on completion
A16: Read | B16: Absorbance Endpoint
B17: Full Plate
B18: Wavelengths: 600
B19: Read Speed: Normal, Delay: 100 msec, Measurements/Data Point: 8
A21: Results
A22: Actual Temperature: | B22: 30
C23: AMS2401 | D23: P75063 | E23: P75016 | F23: L26 | G23: AMS5192 | H23: AMS2401 guide 2 | I23: P75063 guide 2 | J23: P75016 guide 2 | K23: L26 guide 2 | L23: AMS5192 guide 2 | M23: AMS2401 guide 2 transformant 2 | N23: L26 guide 2 transformant 2
C24: 1 | D24: 2 | E24: 3 | F24: 4 | G24: 5 | H24: 6 | I24: 7 | J24: 8 | K24: 9 | L24: 10 | M24: 11 | N24: 12
B25: A | C25: 0.097 | D25: 0.096 | E25: 0.095 | F25: 0.096 | G25: 0.095 | H25: 0.095 | I25: 0.096 | J25: 0.095 | K25: 0.098 | L25: 0.096 | M25: 0.096 | N25: 0.095 | O25: 600 | P25: =AVERAGE(C25:N25) -> 0.095833333
B26: B | C26: 1.283 | D26: 1.445 | E26: 1.407 | F26: 1.395 | G26: 1.433 | H26: 1.424 | I26: 1.451 | J26: 1.384 | K26: 1.405 | L26: 1.425 | M26: 1.422 | N26: 1.412 | O26: 600
B27: C | C27: 1.182 | D27: 1.113 | E27: 1.379 | F27: 1.424 | G27: 1.084 | H27: 1.446 | I27: 1.464 | J27: 1.387 | K27: 1.413 | L27: 1.442 | M27: 1.442 | N27: 1.42 | O27: 600
B28: D | C28: 0.321 | D28: 0.443 | E28: 0.475 | F28: 1.413 | G28: 0.344 | H28: 1.392 | I28: 1.428 | J28: 1.048 | K28: 1.393 | L28: 1.379 | M28: 1.38 | N28: 1.401 | O28: 600
B29: E | C29: 0.264 | D29: 0.3 | E29: 0.331 | F29: 1.437 | G29: 0.274 | H29: 0.381 | I29: 0.373 | J29: 0.327 | K29: 1.403 | L29: 0.349 | M29: 0.289 | N29: 1.396 | O29: 600
B30: F | C30: 0.159 | D30: 0.196 | E30: 0.192 | F30: 0.474 | G30: 0.184 | H30: 0.192 | I30: 0.232 | J30: 0.256 | K30: 1.074 | L30: 0.195 | M30: 0.172 | N30: 1.108 | O30: 600
B31: G | C31: 0.133 | D31: 0.184 | E31: 0.175 | F31: 0.171 | G31: 0.17 | H31: 0.178 | I31: 0.205 | J31: 0.229 | K31: 0.209 | L31: 0.177 | M31: 0.145 | N31: 0.192 | O31: 600
B32: H | C32: 0.125 | D32: 0.18 | E32: 0.154 | F32: 0.139 | G32: 0.162 | H32: 0.164 | I32: 0.206 | J32: 0.226 | K32: 0.162 | L32: 0.177 | M32: 0.134 | N32: 0.139 | O32: 600
C35: =C26-$P$25 -> 1.1871667 | D35: =D26-$P$25 -> 1.3491667 | E35: =E26-$P$25 -> 1.3111667 | F35: =F26-$P$25 -> 1.2991667 | G35: =G26-$P$25 -> 1.3371667 | H35: =H26-$P$25 -> 1.3281667 | I35: =I26-$P$25 -> 1.3551667 | J35: =J26-$P$25 -> 1.2881667 | ... N35: =N26-$P$25 -> 1.3161667
C36: =C27-$P$25 -> 1.0861667 | D36: =D27-$P$25 -> 1.0171667 | E36: =E27-$P$25 -> 1.2831667 | F36: =F27-$P$25 -> 1.3281667 | G36: =G27-$P$25 -> 0.98816667 | H36: =H27-$P$25 -> 1.3501667 | I36: =I27-$P$25 -> 1.3681667 | J36: =J27-$P$25 -> 1.2911667 | ... N36: =N27-$P$25 -> 1.3241667
C37: =C28-$P$25 -> 0.22516667 | D37: =D28-$P$25 -> 0.34716667 | E37: =E28-$P$25 -> 0.37916667 | F37: =F28-$P$25 -> 1.3171667 | G37: =G28-$P$25 -> 0.24816667 | H37: =H28-$P$25 -> 1.2961667 | I37: =I28-$P$25 -> 1.3321667 | J37: =J28-$P$25 -> 0.95216667 | ... N37: =N28-$P$25 -> 1.3051667
C38: =C29-$P$25 -> 0.16816667 | D38: =D29-$P$25 -> 0.20416667 | E38: =E29-$P$25 -> 0.23516667 | F38: =F29-$P$25 -> 1.3411667 | G38: =G29-$P$25 -> 0.17816667 | H38: =H29-$P$25 -> 0.28516667 | I38: =I29-$P$25 -> 0.27716667 | J38: =J29-$P$25 -> 0.23116667 | ... N38: =N29-$P$25 -> 1.3001667
C39: =C30-$P$25 -> 0.063166667 | D39: =D30-$P$25 -> 0.10016667 | E39: =E30-$P$25 -> 0.096166667 | F39: =F30-$P$25 -> 0.37816667 | G39: =G30-$P$25 -> 0.088166667 | H39: =H30-$P$25 -> 0.096166667 | I39: =I30-$P$25 -> 0.13616667 | J39: =J30-$P$25 -> 0.16016667 | ... N39: =N30-$P$25 -> 1.0121667
C40: =C31-$P$25 -> 0.037166667 | D40: =D31-$P$25 -> 0.088166667 | E40: =E31-$P$25 -> 0.079166667 | F40: =F31-$P$25 -> 0.075166667 | G40: =G31-$P$25 -> 0.074166667 | H40: =H31-$P$25 -> 0.082166667 | I40: =I31-$P$25 -> 0.10916667 | J40: =J31-$P$25 -> 0.13316667 | ... N40: =N31-$P$25 -> 0.096166667
C41: =C32-$P$25 -> 0.029166667 | D41: =D32-$P$25 -> 0.084166667 | E41: =E32-$P$25 -> 0.058166667 | F41: =F32-$P$25 -> 0.043166667 | G41: =G32-$P$25 -> 0.066166667 | H41: =H32-$P$25 -> 0.068166667 | I41: =I32-$P$25 -> 0.11016667 | J41: =J32-$P$25 -> 0.13016667 | ... N41: =N32-$P$25 -> 0.043166667
C43: =C35/$C$35 -> 1 | D43: =D35/$D$35 -> 1 | E43: =E35/$E$35 -> 1 | F43: =F35/$F$35 -> 1 | G43: =G35/$G$35 -> 1 | H43: =H35/$H$35 -> 1 | I43: =I35/$I$35 -> 1 | J43: =J35/$J$35 -> 1 | K43: =K35/$K$35 -> 1 | L43: =L35/$L$35 -> 1 | M43: =M35/$M$35 -> 1 | N43: =N35/$N$35 -> 1
C44: =C36/$C$35 -> 0.91492349 | D44: =D36/$D$35 -> 0.75392217 | E44: =E36/$E$35 -> 0.97864497 | F44: =F36/$F$35 -> 1.022322 | G44: =G36/$G$35 -> 0.73900037 | H44: =H36/$H$35 -> 1.0165642 | I44: =I36/$I$35 -> 1.0095929 | J44: =J36/$J$35 -> 1.0023289 | K44: =K36/$K$35 -> 1.0061108 | L44: =L36/$L$35 -> 1.01279 | M44: =M36/$M$35 -> 1.0150811 | N44: =N36/$N$35 -> 1.0060783
C45: =C37/$C$35 -> 0.18966728 | D45: =D37/$D$35 -> 0.25731933 | E45: =E37/$E$35 -> 0.28918266 | F45: =F37/$F$35 -> 1.013855 | G45: =G37/$G$35 -> 0.18559142 | H45: =H37/$H$35 -> 0.97590664 | I45: =I37/$I$35 -> 0.98302792 | J45: =J37/$J$35 -> 0.73916419 | K45: =K37/$K$35 -> 0.99083386 | L45: =L37/$L$35 -> 0.96539185 | M45: =M37/$M$35 -> 0.96832977 | N45: =N37/$N$35 -> 0.9916424
C46: =C38/$C$35 -> 0.1416538 | D46: =D38/$D$35 -> 0.15132798 | E46: =E38/$E$35 -> 0.17935681 | F46: =F38/$F$35 -> 1.0323284 | G46: =G38/$G$35 -> 0.13324193 | H46: =H38/$H$35 -> 0.21470699 | I46: =I38/$I$35 -> 0.20452589 | J46: =J38/$J$35 -> 0.179454 | K46: =K38/$K$35 -> 0.99847231 | L46: =L38/$L$35 -> 0.19047022 | M46: =M38/$M$35 -> 0.14565791 | N46: =N38/$N$35 -> 0.98784348
C47: =C39/$C$35 -> 0.053207918 | D47: =D39/$D$35 -> 0.07424336 | E47: =E39/$E$35 -> 0.07334435 | F47: =F39/$F$35 -> 0.29108403 | G47: =G39/$G$35 -> 0.065935436 | H47: =H39/$H$35 -> 0.072405572 | I47: =I39/$I$35 -> 0.10047965 | J47: =J39/$J$35 -> 0.12433691 | K47: =K39/$K$35 -> 0.74716741 | L47: =L39/$L$35 -> 0.07460815 | M47: =M39/$M$35 -> 0.057433706 | N47: =N39/$N$35 -> 0.76902621
...

Sheet guide2Rep2
A2: Software Version | B2: 3.16.10
A4: Experiment File Path: | B4: C:\Users\Plate Reader Access\Desktop\Selmecki lab\Petra\mic_2025_06_04.xpt
A5: Protocol File Path: | B5: C:\Users\Public\Documents\Protocols\InitialOD.prt
A6: Plate Number | B6: Plate 8
A7: Date | B7: 45812
A8: Time | B8: 0.61775463
A9: Reader Type: | B9: Synergy H1
A10: Reader Serial Number: | B10: 25030902
A11: Reading Type | B11: Reader
A13: Procedure Details
A14: Plate Type | B14: 96 WELL PLATE (Use plate lid)
A15: Eject plate on completion
A16: Read | B16: Absorbance Endpoint
B17: Full Plate
B18: Wavelengths: 600
B19: Read Speed: Normal, Delay: 100 msec, Measurements/Data Point: 8
A21: Results
A22: Actual Temperature: | B22: 29.9
C24: 1 | D24: 2 | E24: 3 | F24: 4 | G24: 5 | H24: 6 | I24: 7 | J24: 8 | K24: 9 | L24: 10 | M24: 11 | N24: 12
B25: A | C25: 0.097 | D25: 0.097 | E25: 0.097 | F25: 0.096 | G25: 0.095 | H25: 0.095 | I25: 0.096 | J25: 0.095 | K25: 0.096 | L25: 0.096 | M25: 0.095 | N25: 0.096 | O25: 600 | P25: =AVERAGE(C25:N25) -> 0.095916667
B26: B | C26: 1.275 | D26: 1.452 | E26: 1.345 | F26: 1.397 | G26: 1.389 | H26: 1.363 | I26: 1.399 | J26: 1.387 | K26: 1.377 | L26: 1.41 | M26: 1.381 | N26: 1.392 | O26: 600
B27: C | C27: 1.134 | D27: 1.119 | E27: 1.337 | F27: 1.397 | G27: 1.24 | H27: 1.391 | I27: 1.414 | J27: 1.409 | K27: 1.366 | L27: 1.397 | M27: 1.38 | N27: 1.374 | O27: 600
B28: D | C28: 0.354 | D28: 0.466 | E28: 0.508 | F28: 1.467 | G28: 0.415 | H28: 1.399 | I28: 1.45 | J28: 1.037 | K28: 1.442 | L28: 1.396 | M28: 1.375 | N28: 1.411 | O28: 600
B29: E | C29: 0.207 | D29: 0.249 | E29: 0.275 | F29: 1.395 | G29: 0.249 | H29: 0.404 | I29: 0.421 | J29: 0.358 | K29: 1.44 | L29: 0.359 | M29: 0.323 | N29: 1.411 | O29: 600
B30: F | C30: 0.147 | D30: 0.197 | E30: 0.174 | F30: 0.499 | G30: 0.182 | H30: 0.217 | I30: 0.251 | J30: 0.274 | K30: 1.099 | L30: 0.21 | M30: 0.172 | N30: 1.086 | O30: 600
B31: G | C31: 0.136 | D31: 0.181 | E31: 0.153 | F31: 0.175 | G31: 0.159 | H31: 0.17 | I31: 0.217 | J31: 0.236 | K31: 0.225 | L31: 0.189 | M31: 0.141 | N31: 0.196 | O31: 600
B32: H | C32: 0.127 | D32: 0.177 | E32: 0.139 | F32: 0.136 | G32: 0.138 | H32: 0.165 | I32: 0.207 | J32: 0.231 | K32: 0.163 | L32: 0.179 | M32: 0.136 | N32: 0.144 | O32: 600
C35: =C26-$P$25 -> 1.1790833 | D35: =D26-$P$25 -> 1.3560833 | E35: =E26-$P$25 -> 1.2490833 | F35: =F26-$P$25 -> 1.3010833 | G35: =G26-$P$25 -> 1.2930833 | H35: =H26-$P$25 -> 1.2670833 | I35: =I26-$P$25 -> 1.3030833 | J35: =J26-$P$25 -> 1.2910833 | ... N35: =N26-$P$25 -> 1.2960833
C36: =C27-$P$25 -> 1.0380833 | D36: =D27-$P$25 -> 1.0230833 | E36: =E27-$P$25 -> 1.2410833 | F36: =F27-$P$25 -> 1.3010833 | G36: =G27-$P$25 -> 1.1440833 | H36: =H27-$P$25 -> 1.2950833 | I36: =I27-$P$25 -> 1.3180833 | J36: =J27-$P$25 -> 1.3130833 | ... N36: =N27-$P$25 -> 1.2780833
C37: =C28-$P$25 -> 0.25808333 | D37: =D28-$P$25 -> 0.37008333 | E37: =E28-$P$25 -> 0.41208333 | F37: =F28-$P$25 -> 1.3710833 | G37: =G28-$P$25 -> 0.31908333 | H37: =H28-$P$25 -> 1.3030833 | I37: =I28-$P$25 -> 1.3540833 | J37: =J28-$P$25 -> 0.94108333 | ... N37: =N28-$P$25 -> 1.3150833
C38: =C29-$P$25 -> 0.11108333 | D38: =D29-$P$25 -> 0.15308333 | E38: =E29-$P$25 -> 0.17908333 | F38: =F29-$P$25 -> 1.2990833 | G38: =G29-$P$25 -> 0.15308333 | H38: =H29-$P$25 -> 0.30808333 | I38: =I29-$P$25 -> 0.32508333 | J38: =J29-$P$25 -> 0.26208333 | ... N38: =N29-$P$25 -> 1.3150833
C39: =C30-$P$25 -> 0.051083333 | D39: =D30-$P$25 -> 0.10108333 | E39: =E30-$P$25 -> 0.078083333 | F39: =F30-$P$25 -> 0.40308333 | G39: =G30-$P$25 -> 0.086083333 | H39: =H30-$P$25 -> 0.12108333 | I39: =I30-$P$25 -> 0.15508333 | J39: =J30-$P$25 -> 0.17808333 | ... N39: =N30-$P$25 -> 0.99008333
C40: =C31-$P$25 -> 0.040083333 | D40: =D31-$P$25 -> 0.085083333 | E40: =E31-$P$25 -> 0.057083333 | F40: =F31-$P$25 -> 0.079083333 | G40: =G31-$P$25 -> 0.063083333 | H40: =H31-$P$25 -> 0.074083333 | I40: =I31-$P$25 -> 0.12108333 | J40: =J31-$P$25 -> 0.14008333 | ... N40: =N31-$P$25 -> 0.10008333
C41: =C32-$P$25 -> 0.031083333 | D41: =D32-$P$25 -> 0.081083333 | E41: =E32-$P$25 -> 0.043083333 | F41: =F32-$P$25 -> 0.040083333 | G41: =G32-$P$25 -> 0.042083333 | H41: =H32-$P$25 -> 0.069083333 | I41: =I32-$P$25 -> 0.11108333 | J41: =J32-$P$25 -> 0.13508333 | ... N41: =N32-$P$25 -> 0.048083333
C43: =C35/$C$35 -> 1 | D43: =D35/$D$35 -> 1 | E43: =E35/$E$35 -> 1 | F43: =F35/$F$35 -> 1 | G43: =G35/$G$35 -> 1 | H43: =H35/$H$35 -> 1 | I43: =I35/$I$35 -> 1 | J43: =J35/$J$35 -> 1 | K43: =K35/$K$35 -> 1 | L43: =L35/$L$35 -> 1 | M43: =M35/$M$35 -> 1 | N43: =N35/$N$35 -> 1
C44: =C36/$C$35 -> 0.88041558 | D44: =D36/$D$35 -> 0.75443987 | E44: =E36/$E$35 -> 0.9935953 | F44: =F36/$F$35 -> 1 | G44: =G36/$G$35 -> 0.88477154 | H44: =H36/$H$35 -> 1.022098 | I44: =I36/$I$35 -> 1.0115112 | J44: =J36/$J$35 -> 1.01704 | K44: =K36/$K$35 -> 0.99141352 | L44: =L36/$L$35 -> 0.99010717 | M44: =M36/$M$35 -> 0.99922184 | N44: =N36/$N$35 -> 0.986112
C45: =C37/$C$35 -> 0.21888473 | D45: =D37/$D$35 -> 0.27290604 | E45: =E37/$E$35 -> 0.3299086 | F45: =F37/$F$35 -> 1.0538013 | G45: =G37/$G$35 -> 0.24676162 | H45: =H37/$H$35 -> 1.0284117 | I45: =I37/$I$35 -> 1.0391379 | J45: =J37/$J$35 -> 0.72890983 | K45: =K37/$K$35 -> 1.0507383 | L45: =L37/$L$35 -> 0.98934619 | M45: =M37/$M$35 -> 0.99533104 | N45: =N37/$N$35 -> 1.0146596
C46: =C38/$C$35 -> 0.094211605 | D46: =D38/$D$35 -> 0.11288638 | E46: =E38/$E$35 -> 0.14337181 | F46: =F38/$F$35 -> 0.99846282 | G46: =G38/$G$35 -> 0.11838629 | H46: =H38/$H$35 -> 0.2431437 | I46: =I38/$I$35 -> 0.24947241 | J46: =J38/$J$35 -> 0.2029949 | K46: =K38/$K$35 -> 1.0491771 | L46: =L38/$L$35 -> 0.20020293 | M46: =M38/$M$35 -> 0.17670709 | N46: =N38/$N$35 -> 1.0146596
C47: =C39/$C$35 -> 0.043324617 | D47: =D39/$D$35 -> 0.07454065 | E47: =E39/$E$35 -> 0.062512509 | F47: =F39/$F$35 -> 0.30980593 | G47: =G39/$G$35 -> 0.066572147 | H47: =H39/$H$35 -> 0.095560671 | I47: =I39/$I$35 -> 0.1190126 | J47: =J39/$J$35 -> 0.13793326 | K47: =K39/$K$35 -> 0.78299616 | L47: =L39/$L$35 -> 0.086815905 | M47: =M39/$M$35 -> 0.05920498 | N47: =N39/$N$35 -> 0.76390407
C48: =C40/$C$35 -> 0.033995335 | D48: =D40/$D$35 -> 0.062741965 | E48: =E40/$E$35 -> 0.04570018 | F48: =F40/$F$35 -> 0.060782681 | G48: =G40/$G$35 -> 0.048785203 | H48: =H40/$H$35 -> 0.058467609 | I48: =I40/$I$35 -> 0.092920637 | J48: =J40/$J$35 -> 0.10850061 | K48: =K40/$K$35 -> 0.10076107 | L48: =L40/$L$35 -> 0.070835183 | M48: =M40/$M$35 -> 0.035082031 | N48: =N40/$N$35 -> 0.077219829
...

Sheet guide2Rep3, analysis
A2: Software Version | B2: 3.16.10
A4: Experiment File Path: | B4: C:\Users\Plate Reader Access\Desktop\Selmecki lab\Petra\mic_2025_06_04.xpt
A5: Protocol File Path: | B5: C:\Users\Public\Documents\Protocols\InitialOD.prt
A6: Plate Number | B6: Plate 9
A7: Date | B7: 45812
A8: Time | B8: 0.61858796
A9: Reader Type: | B9: Synergy H1
A10: Reader Serial Number: | B10: 25030902
A11: Reading Type | B11: Reader
A13: Procedure Details
A14: Plate Type | B14: 96 WELL PLATE (Use plate lid)
A15: Eject plate on completion
A16: Read | B16: Absorbance Endpoint
B17: Full Plate
B18: Wavelengths: 600
B19: Read Speed: Normal, Delay: 100 msec, Measurements/Data Point: 8
A21: Results
A22: Actual Temperature: | B22: 29.8
C24: 1 | D24: 2 | E24: 3 | F24: 4 | G24: 5 | H24: 6 | I24: 7 | J24: 8 | K24: 9 | L24: 10 | M24: 11 | N24: 12
B25: A | C25: 0.097 | D25: 0.096 | E25: 0.096 | F25: 0.096 | G25: 0.096 | H25: 0.096 | I25: 0.104 | J25: 0.098 | K25: 0.098 | L25: 0.096 | M25: 0.095 | N25: 0.096 | O25: 600 | P25: =AVERAGE(C25:N25) -> 0.097
B26: B | C26: 1.312 | D26: 1.4 | E26: 1.362 | F26: 1.408 | G26: 1.381 | H26: 1.387 | I26: 1.47 | J26: 1.402 | K26: 1.409 | L26: 1.443 | M26: 1.446 | N26: 1.434 | O26: 600
B27: C | C27: 1.123 | D27: 1.128 | E27: 1.391 | F27: 1.438 | G27: 1.138 | H27: 1.427 | I27: 1.484 | J27: 1.425 | K27: 1.401 | L27: 1.399 | M27: 1.395 | N27: 1.386 | O27: 600
B28: D | C28: 0.386 | D28: 0.468 | E28: 0.484 | F28: 1.437 | G28: 0.343 | H28: 1.401 | I28: 1.438 | J28: 1.044 | K28: 1.422 | L28: 1.397 | M28: 1.404 | N28: 1.44 | O28: 600
B29: E | C29: 0.224 | D29: 0.249 | E29: 0.232 | F29: 1.383 | G29: 0.215 | H29: 0.399 | I29: 0.414 | J29: 0.362 | K29: 1.419 | L29: 0.372 | M29: 0.335 | N29: 1.401 | O29: 600
B30: F | C30: 0.149 | D30: 0.199 | E30: 0.175 | F30: 0.485 | G30: 0.174 | H30: 0.201 | I30: 0.232 | J30: 0.258 | K30: 1.082 | L30: 0.206 | M30: 0.165 | N30: 1.058 | O30: 600
B31: G | C31: 0.142 | D31: 0.178 | E31: 0.146 | F31: 0.179 | G31: 0.149 | H31: 0.168 | I31: 0.223 | J31: 0.228 | K31: 0.228 | L31: 0.182 | M31: 0.141 | N31: 0.199 | O31: 600
B32: H | C32: 0.129 | D32: 0.177 | E32: 0.135 | F32: 0.141 | G32: 0.134 | H32: 0.149 | I32: 0.215 | J32: 0.22 | K32: 0.153 | L32: 0.175 | M32: 0.133 | N32: 0.143 | O32: 600
C35: =C26-$P$25 -> 1.215 | D35: =D26-$P$25 -> 1.303 | E35: =E26-$P$25 -> 1.265 | F35: =F26-$P$25 -> 1.311 | G35: =G26-$P$25 -> 1.284 | H35: =H26-$P$25 -> 1.29 | I35: =I26-$P$25 -> 1.373 | J35: =J26-$P$25 -> 1.305 | ... N35: =N26-$P$25 -> 1.337
C36: =C27-$P$25 -> 1.026 | D36: =D27-$P$25 -> 1.031 | E36: =E27-$P$25 -> 1.294 | F36: =F27-$P$25 -> 1.341 | G36: =G27-$P$25 -> 1.041 | H36: =H27-$P$25 -> 1.33 | I36: =I27-$P$25 -> 1.387 | J36: =J27-$P$25 -> 1.328 | ... N36: =N27-$P$25 -> 1.289
C37: =C28-$P$25 -> 0.289 | D37: =D28-$P$25 -> 0.371 | E37: =E28-$P$25 -> 0.387 | F37: =F28-$P$25 -> 1.34 | G37: =G28-$P$25 -> 0.246 | H37: =H28-$P$25 -> 1.304 | I37: =I28-$P$25 -> 1.341 | J37: =J28-$P$25 -> 0.947 | ... N37: =N28-$P$25 -> 1.343
C38: =C29-$P$25 -> 0.127 | D38: =D29-$P$25 -> 0.152 | E38: =E29-$P$25 -> 0.135 | F38: =F29-$P$25 -> 1.286 | G38: =G29-$P$25 -> 0.118 | H38: =H29-$P$25 -> 0.302 | I38: =I29-$P$25 -> 0.317 | J38: =J29-$P$25 -> 0.265 | ... N38: =N29-$P$25 -> 1.304
C39: =C30-$P$25 -> 0.052 | D39: =D30-$P$25 -> 0.102 | E39: =E30-$P$25 -> 0.078 | F39: =F30-$P$25 -> 0.388 | G39: =G30-$P$25 -> 0.077 | H39: =H30-$P$25 -> 0.104 | I39: =I30-$P$25 -> 0.135 | J39: =J30-$P$25 -> 0.161 | ... N39: =N30-$P$25 -> 0.961
C40: =C31-$P$25 -> 0.045 | D40: =D31-$P$25 -> 0.081 | E40: =E31-$P$25 -> 0.049 | F40: =F31-$P$25 -> 0.082 | G40: =G31-$P$25 -> 0.052 | H40: =H31-$P$25 -> 0.071 | I40: =I31-$P$25 -> 0.126 | J40: =J31-$P$25 -> 0.131 | ... N40: =N31-$P$25 -> 0.102
C41: =C32-$P$25 -> 0.032 | D41: =D32-$P$25 -> 0.08 | E41: =E32-$P$25 -> 0.038 | F41: =F32-$P$25 -> 0.044 | G41: =G32-$P$25 -> 0.037 | H41: =H32-$P$25 -> 0.052 | I41: =I32-$P$25 -> 0.118 | J41: =J32-$P$25 -> 0.123 | ... N41: =N32-$P$25 -> 0.046
C43: =C35/$C$35 -> 1 | D43: =D35/$D$35 -> 1 | E43: =E35/$E$35 -> 1 | F43: =F35/$F$35 -> 1 | G43: =G35/$G$35 -> 1 | H43: =H35/$H$35 -> 1 | I43: =I35/$I$35 -> 1 | J43: =J35/$J$35 -> 1 | K43: =K35/$K$35 -> 1 | L43: =L35/$L$35 -> 1 | M43: =M35/$M$35 -> 1 | N43: =N35/$N$35 -> 1
C44: =C36/$C$35 -> 0.84444444 | D44: =D36/$D$35 -> 0.79125096 | E44: =E36/$E$35 -> 1.0229249 | F44: =F36/$F$35 -> 1.0228833 | G44: =G36/$G$35 -> 0.81074766 | H44: =H36/$H$35 -> 1.0310078 | I44: =I36/$I$35 -> 1.0101966 | J44: =J36/$J$35 -> 1.0176245 | K44: =K36/$K$35 -> 0.99390244 | L44: =L36/$L$35 -> 0.96731055 | M44: =M36/$M$35 -> 0.96219422 | N44: =N36/$N$35 -> 0.96409873
C45: =C37/$C$35 -> 0.23786008 | D45: =D37/$D$35 -> 0.28472755 | E45: =E37/$E$35 -> 0.30592885 | F45: =F37/$F$35 -> 1.0221205 | G45: =G37/$G$35 -> 0.19158879 | H45: =H37/$H$35 -> 1.0108527 | I45: =I37/$I$35 -> 0.97669337 | J45: =J37/$J$35 -> 0.7256705 | K45: =K37/$K$35 -> 1.0099085 | L45: =L37/$L$35 -> 0.96582467 | M45: =M37/$M$35 -> 0.96886583 | N45: =N37/$N$35 -> 1.0044877
C46: =C38/$C$35 -> 0.10452675 | D46: =D38/$D$35 -> 0.11665388 | E46: =E38/$E$35 -> 0.10671937 | F46: =F38/$F$35 -> 0.98093059 | G46: =G38/$G$35 -> 0.091900312 | H46: =H38/$H$35 -> 0.23410853 | I46: =I38/$I$35 -> 0.23088128 | J46: =J38/$J$35 -> 0.20306513 | K46: =K38/$K$35 -> 1.007622 | L46: =L38/$L$35 -> 0.20430906 | M46: =M38/$M$35 -> 0.17642698 | N46: =N38/$N$35 -> 0.97531788
C47: =C39/$C$35 -> 0.042798354 | D47: =D39/$D$35 -> 0.07828089 | E47: =E39/$E$35 -> 0.061660079 | F47: =F39/$F$35 -> 0.29595728 | G47: =G39/$G$35 -> 0.059968847 | H47: =H39/$H$35 -> 0.080620155 | I47: =I39/$I$35 -> 0.098324836 | J47: =J39/$J$35 -> 0.12337165 | K47: =K39/$K$35 -> 0.7507622 | L47: =L39/$L$35 -> 0.080980684 | M47: =M39/$M$35 -> 0.050407709 | N47: =N39/$N$35 -> 0.71877337
C48: =C40/$C$35 -> 0.037037037 | D48: =D40/$D$35 -> 0.062164236 | E48: =E40/$E$35 -> 0.038735178 | F48: =F40/$F$35 -> 0.062547674 | G48: =G40/$G$35 -> 0.040498442 | H48: =H40/$H$35 -> 0.05503876 | I48: =I40/$I$35 -> 0.091769847 | J48: =J40/$J$35 -> 0.10038314 | K48: =K40/$K$35 -> 0.099847561 | L48: =L40/$L$35 -> 0.063150074 | M48: =M40/$M$35 -> 0.032616753 | N48: =N40/$N$35 -> 0.076290202
...
